Workbook

Sheet Employee Information
A1: Employee ID | B1: Employee Name | C1: Department | D1: Hire Date
A2: EMP1001 | B2: Employee 1 | C2: Operations | D2: 2022-01-23
A3: EMP1002 | B3: Employee 2 | C3: Admin | D3: 2025-08-26
A4: EMP1003 | B4: Employee 3 | C4: Finance | D4: 2020-11-16
A5: EMP1004 | B5: Employee 4 | C5: Sales | D5: 2024-04-19
A6: EMP1005 | B6: Employee 5 | C6: Sales | D6: 2023-08-17
A7: EMP1006 | B7: Employee 6 | C7: HR | D7: 2021-03-15
A8: EMP1007 | B8: Employee 7 | C8: Operations | D8: 2024-10-09
A9: EMP1008 | B9: Employee 8 | C9: IT | D9: 2021-08-19
A10: EMP1009 | B10: Employee 9 | C10: Operations | D10: 2023-11-05
A11: EMP1010 | B11: Employee 10 | C11: Sales | D11: 2020-06-18
A12: EMP1011 | B12: Employee 11 | C12: Sales | D12: 2024-11-23
... A61: EMP1060 | B61: Employee 60 | C61: Procurement | D61: 2025-01-08

Sheet Performance Records
A1: Employee ID | B1: Performance Score
A2: EMP1001 | B2: 56
A3: EMP1002 | B3: 88
A4: EMP1003 | B4: 68
A5: EMP1004 | B5: 95
A6: EMP1005 | B6: 83
A7: EMP1006 | B7: 48
A8: EMP1007 | B8: 89
A9: EMP1009 | B9: 84
A10: EMP1010 | B10: 63
A11: EMP1011 | B11: 81
A12: EMP1012 | B12: 81
A13: EMP1013 | B13: 74
... A56: EMP1060 | B56: 56

Sheet Performance summary
B1: HAVEN ORDER COMPANY - EMPLOYEE PERFORMANCE SUMMARY
A3: EMPLOYEE ID | B3: EMPLOYEE NAME | C3: DEPARTMENT | D3: PERFORMANCE SCORE | E3: PERFORMANCE RATING | F3: BONUS ELIGIBILITY
A4: =('Employee Information'!A2) -> EMP1001 | B4: =VLOOKUP(A4,'Employee Information'!A:D,2,FALSE) -> Employee 1 | C4: =VLOOKUP(A4,'Employee Information'!A:C,3,FALSE) -> Operations | D4: =IFERROR(VLOOKUP(A4,'Performance Records'!A:B,2,FALSE),"PENDING REVIEW") -> 56 | E4: =IF(D4="PENDING REVIEW","PENDING REVIEW",IF(D4>90,"EXCELLENT",IF(D4>75,"GOOD",IF(D4>60,"AVERAGE","NEEDS IMPROVEMENT")))) -> NEEDS IMPROVEMENT | F4: =IF(E4="PENDING REVIEW"," PENDING REVIEW",IF(OR(E4="EXCELLENT",E4="GOOD"),"ELIGIBLE","NOT ELIGIBLE")) -> NOT ELIGIBLE
A5: =('Employee Information'!A3) -> EMP1002 | B5: =VLOOKUP(A5,'Employee Information'!A:D,2,FALSE) -> Employee 2 | C5: =VLOOKUP(A5,'Employee Information'!A:C,3,FALSE) -> Admin | D5: =IFERROR(VLOOKUP(A5,'Performance Records'!A:B,2,FALSE),"PENDING REVIEW") -> 88 | E5: =IF(D5="PENDING REVIEW","PENDING REVIEW",IF(D5>90,"EXCELLENT",IF(D5>75,"GOOD",IF(D5>60,"AVERAGE","NEEDS IMPROVEMENT")))) -> GOOD | F5: =IF(E5="PENDING REVIEW"," PENDING REVIEW",IF(OR(E5="EXCELLENT",E5="GOOD"),"ELIGIBLE","NOTELIGIBLE")) -> ELIGIBLE
A6: =('Employee Information'!A4) -> EMP1003 | B6: =VLOOKUP(A6,'Employee Information'!A:D,2,FALSE) -> Employee 3 | C6: =VLOOKUP(A6,'Employee Information'!A:C,3,FALSE) -> Finance | D6: =IFERROR(VLOOKUP(A6,'Performance Records'!A:B,2,FALSE),"PENDING REVIEW") -> 68 | E6: =IF(D6="PENDING REVIEW","PENDING REVIEW",IF(D6>90,"EXCELLENT",IF(D6>75,"GOOD",IF(D6>60,"AVERAGE","NEEDS IMPROVEMENT")))) -> AVERAGE | F6: =IF(E6="PENDING REVIEW"," PENDING REVIEW",IF(OR(E6="EXCELLENT",E6="GOOD"),"ELIGIBLE","NOT ELIGIBLE")) -> NOT ELIGIBLE
A7: =('Employee Information'!A5) -> EMP1004 | B7: =VLOOKUP(A7,'Employee Information'!A:D,2,FALSE) -> Employee 4 | C7: =VLOOKUP(A7,'Employee Information'!A:C,3,FALSE) -> Sales | D7: =IFERROR(VLOOKUP(A7,'Performance Records'!A:B,2,FALSE),"PENDING REVIEW") -> 95 | E7: =IF(D7="PENDING REVIEW","PENDING REVIEW",IF(D7>90,"EXCELLENT",IF(D7>75,"GOOD",IF(D7>60,"AVERAGE","NEEDS IMPROVEMENT")))) -> EXCELLENT | F7: =IF(E7="PENDING REVIEW"," PENDING REVIEW",IF(OR(E7="EXCELLENT",E7="GOOD"),"ELIGIBLE","NOTELIGIBLE")) -> ELIGIBLE
A8: =('Employee Information'!A6) -> EMP1005 | B8: =VLOOKUP(A8,'Employee Information'!A:D,2,FALSE) -> Employee 5 | C8: =VLOOKUP(A8,'Employee Information'!A:C,3,FALSE) -> Sales | D8: =IFERROR(VLOOKUP(A8,'Performance Records'!A:B,2,FALSE),"PENDING REVIEW") -> PENDING REVIEW | E8: =IF(D8="PENDING REVIEW","PENDING REVIEW",IF(D8>90,"EXCELLENT",IF(D8>75,"GOOD",IF(D8>60,"AVERAGE","NEEDS IMPROVEMENT")))) -> PENDING REVIEW | F8: =IF(E8="PENDING REVIEW"," PENDING REVIEW",IF(OR(E8="EXCELLENT",E8="GOOD"),"ELIGIBLE","NOTELIGIBLE")) -> PENDING REVIEW
A9: =('Employee Information'!A7) -> EMP1006 | B9: =VLOOKUP(A9,'Employee Information'!A:D,2,FALSE) -> Employee 6 | C9: =VLOOKUP(A9,'Employee Information'!A:C,3,FALSE) -> HR | D9: =IFERROR(VLOOKUP(A9,'Performance Records'!A:B,2,FALSE),"PENDING REVIEW") -> 48 | E9: =IF(D9="PENDING REVIEW","PENDING REVIEW",IF(D9>90,"EXCELLENT",IF(D9>75,"GOOD",IF(D9>60,"AVERAGE","NEEDS IMPROVEMENT")))) -> NEEDS IMPROVEMENT | F9: =IF(E9="PENDING REVIEW"," PENDING REVIEW",IF(OR(E9="EXCELLENT",E9="GOOD"),"ELIGIBLE","NOT ELIGIBLE")) -> NOT ELIGIBLE
A10: =('Employee Information'!A8) -> EMP1007 | B10: =VLOOKUP(A10,'Employee Information'!A:D,2,FALSE) -> Employee 7 | C10: =VLOOKUP(A10,'Employee Information'!A:C,3,FALSE) -> Operations | D10: =IFERROR(VLOOKUP(A10,'Performance Records'!A:B,2,FALSE),"PENDING REVIEW") -> 89 | E10: =IF(D10="PENDING REVIEW","PENDING REVIEW",IF(D10>90,"EXCELLENT",IF(D10>75,"GOOD",IF(D10>60,"AVERAGE","NEEDS IMPROVEMENT")))) -> GOOD | F10: =IF(E10="PENDING REVIEW"," PENDING REVIEW",IF(OR(E10="EXCELLENT",E10="GOOD"),"ELIGIBLE","NOTELIGIBLE")) -> ELIGIBLE
A11: =('Employee Information'!A9) -> EMP1008 | B11: =VLOOKUP(A11,'Employee Information'!A:D,2,FALSE) -> Employee 8 | C11: =VLOOKUP(A11,'Employee Information'!A:C,3,FALSE) -> IT | D11: =IFERROR(VLOOKUP(A11,'Performance Records'!A:B,2,FALSE),"PENDING REVIEW") -> PENDING REVIEW | E11: =IF(D11="PENDING REVIEW","PENDING REVIEW",IF(D11>90,"EXCELLENT",IF(D11>75,"GOOD",IF(D11>60,"AVERAGE","NEEDS IMPROVEMENT")))) -> PENDING REVIEW | F11: =IF(E11="PENDING REVIEW"," PENDING REVIEW",IF(OR(E11="EXCELLENT",E11="GOOD"),"ELIGIBLE","NOTELIGIBLE")) -> PENDING REVIEW
A12: =('Employee Information'!A10) -> EMP1009 | B12: =VLOOKUP(A12,'Employee Information'!A:D,2,FALSE) -> Employee 9 | C12: =VLOOKUP(A12,'Employee Information'!A:C,3,FALSE) -> Operations | D12: =IFERROR(VLOOKUP(A12,'Performance Records'!A:B,2,FALSE),"PENDING REVIEW") -> 84 | E12: =IF(D12="PENDING REVIEW","PENDING REVIEW",IF(D12>90,"EXCELLENT",IF(D12>75,"GOOD",IF(D12>60,"AVERAGE","NEEDS IMPROVEMENT")))) -> GOOD | F12: =IF(E12="PENDING REVIEW"," PENDING REVIEW",IF(OR(E12="EXCELLENT",E12="GOOD"),"ELIGIBLE","NOTELIGIBLE")) -> ELIGIBLE
A13: =('Employee Information'!A11) -> EMP1010 | B13: =VLOOKUP(A13,'Employee Information'!A:D,2,FALSE) -> Employee 10 | C13: =VLOOKUP(A13,'Employee Information'!A:C,3,FALSE) -> Sales | D13: =IFERROR(VLOOKUP(A13,'Performance Records'!A:B,2,FALSE),"PENDING REVIEW") -> 63 | E13: =IF(D13="PENDING REVIEW","PENDING REVIEW",IF(D13>90,"EXCELLENT",IF(D13>75,"GOOD",IF(D13>60,"AVERAGE","NEEDS IMPROVEMENT")))) -> AVERAGE | F13: =IF(E13="PENDING REVIEW"," PENDING REVIEW",IF(OR(E13="EXCELLENT",E13="GOOD"),"ELIGIBLE","NOT ELIGIBLE")) -> NOT ELIGIBLE
A14: =('Employee Information'!A12) -> EMP1011 | B14: =VLOOKUP(A14,'Employee Information'!A:D,2,FALSE) -> Employee 11 | C14: =VLOOKUP(A14,'Employee Information'!A:C,3,FALSE) -> Sales | D14: =IFERROR(VLOOKUP(A14,'Performance Records'!A:B,2,FALSE),"PENDING REVIEW") -> 81 | E14: =IF(D14="PENDING REVIEW","PENDING REVIEW",IF(D14>90,"EXCELLENT",IF(D14>75,"GOOD",IF(D14>60,"AVERAGE","NEEDS IMPROVEMENT")))) -> GOOD | F14: =IF(E14="PENDING REVIEW"," PENDING REVIEW",IF(OR(E14="EXCELLENT",E14="GOOD"),"ELIGIBLE","NOTELIGIBLE")) -> ELIGIBLE
A15: =('Employee Information'!A13) -> EMP1012 | B15: =VLOOKUP(A15,'Employee Information'!A:D,2,FALSE) -> Employee 12 | C15: =VLOOKUP(A15,'Employee Information'!A:C,3,FALSE) -> IT | D15: =IFERROR(VLOOKUP(A15,'Performance Records'!A:B,2,FALSE),"PENDING REVIEW") -> 81 | E15: =IF(D15="PENDING REVIEW","PENDING REVIEW",IF(D15>90,"EXCELLENT",IF(D15>75,"GOOD",IF(D15>60,"AVERAGE","NEEDS IMPROVEMENT")))) -> GOOD | F15: =IF(E15="PENDING REVIEW"," PENDING REVIEW",IF(OR(E15="EXCELLENT",E15="GOOD"),"ELIGIBLE","NOTELIGIBLE")) -> ELIGIBLE
A16: =('Employee Information'!A14) -> EMP1013 | B16: =VLOOKUP(A16,'Employee Information'!A:D,2,FALSE) -> Employee 13 | C16: =VLOOKUP(A16,'Employee Information'!A:C,3,FALSE) -> Finance | D16: =IFERROR(VLOOKUP(A16,'Performance Records'!A:B,2,FALSE),"PENDING REVIEW") -> 74 | E16: =IF(D16="PENDING REVIEW","PENDING REVIEW",IF(D16>90,"EXCELLENT",IF(D16>75,"GOOD",IF(D16>60,"AVERAGE","NEEDS IMPROVEMENT")))) -> AVERAGE | F16: =IF(E16="PENDING REVIEW"," PENDING REVIEW",IF(OR(E16="EXCELLENT",E16="GOOD"),"ELIGIBLE","NOT ELIGIBLE")) -> NOT ELIGIBLE
A17: =('Employee Information'!A15) -> EMP1014 | B17: =VLOOKUP(A17,'Employee Information'!A:D,2,FALSE) -> Employee 14 | C17: =VLOOKUP(A17,'Employee Information'!A:C,3,FALSE) -> IT | D17: =IFERROR(VLOOKUP(A17,'Performance Records'!A:B,2,FALSE),"PENDING REVIEW") -> 83 | E17: =IF(D17="PENDING REVIEW","PENDING REVIEW",IF(D17>90,"EXCELLENT",IF(D17>75,"GOOD",IF(D17>60,"AVERAGE","NEEDS IMPROVEMENT")))) -> GOOD | F17: =IF(E17="PENDING REVIEW"," PENDING REVIEW",IF(OR(E17="EXCELLENT",E17="GOOD"),"ELIGIBLE","NOTELIGIBLE")) -> ELIGIBLE
A18: =('Employee Information'!A16) -> EMP1015 | B18: =VLOOKUP(A18,'Employee Information'!A:D,2,FALSE) -> Employee 15 | C18: =VLOOKUP(A18,'Employee Information'!A:C,3,FALSE) -> Sales | D18: =IFERROR(VLOOKUP(A18,'Performance Records'!A:B,2,FALSE),"PENDING REVIEW") -> 85 | E18: =IF(D18="PENDING REVIEW","PENDING REVIEW",IF(D18>90,"EXCELLENT",IF(D18>75,"GOOD",IF(D18>60,"AVERAGE","NEEDS IMPROVEMENT")))) -> GOOD | F18: =IF(E18="PENDING REVIEW"," PENDING REVIEW",IF(OR(E18="EXCELLENT",E18="GOOD"),"ELIGIBLE","NOTELIGIBLE")) -> ELIGIBLE
A19: =('Employee Information'!A17) -> EMP1016 | B19: =VLOOKUP(A19,'Employee Information'!A:D,2,FALSE) -> Employee 16 | C19: =VLOOKUP(A19,'Employee Information'!A:C,3,FALSE) -> Finance | D19: =IFERROR(VLOOKUP(A19,'Performance Records'!A:B,2,FALSE),"PENDING REVIEW") -> 52 | E19: =IF(D19="PENDING REVIEW","PENDING REVIEW",IF(D19>90,"EXCELLENT",IF(D19>75,"GOOD",IF(D19>60,"AVERAGE","NEEDS IMPROVEMENT")))) -> NEEDS IMPROVEMENT | F19: =IF(E19="PENDING REVIEW"," PENDING REVIEW",IF(OR(E19="EXCELLENT",E19="GOOD"),"ELIGIBLE","NOT ELIGIBLE")) -> NOT ELIGIBLE
A20: =('Employee Information'!A18) -> EMP1017 | B20: =VLOOKUP(A20,'Employee Information'!A:D,2,FALSE) -> Employee 17 | C20: =VLOOKUP(A20,'Employee Information'!A:C,3,FALSE) -> Procurement | D20: =IFERROR(VLOOKUP(A20,'Performance Records'!A:B,2,FALSE),"PENDING REVIEW") -> 90 | E20: =IF(D20="PENDING REVIEW","PENDING REVIEW",IF(D20>90,"EXCELLENT",IF(D20>75,"GOOD",IF(D20>60,"AVERAGE","NEEDS IMPROVEMENT")))) -> GOOD | F20: =IF(E20="PENDING REVIEW"," PENDING REVIEW",IF(OR(E20="EXCELLENT",E20="GOOD"),"ELIGIBLE","NOTELIGIBLE")) -> ELIGIBLE
A21: =('Employee Information'!A19) -> EMP1018 | B21: =VLOOKUP(A21,'Employee Information'!A:D,2,FALSE) -> Employee 18 | C21: =VLOOKUP(A21,'Employee Information'!A:C,3,FALSE) -> Operations | D21: =IFERROR(VLOOKUP(A21,'Performance Records'!A:B,2,FALSE),"PENDING REVIEW") -> PENDING REVIEW | E21: =IF(D21="PENDING REVIEW","PENDING REVIEW",IF(D21>90,"EXCELLENT",IF(D21>75,"GOOD",IF(D21>60,"AVERAGE","NEEDS IMPROVEMENT")))) -> PENDING REVIEW | F21: =IF(E21="PENDING REVIEW"," PENDING REVIEW",IF(OR(E21="EXCELLENT",E21="GOOD"),"ELIGIBLE","NOTELIGIBLE")) -> PENDING REVIEW
A22: =('Employee Information'!A20) -> EMP1019 | B22: =VLOOKUP(A22,'Employee Information'!A:D,2,FALSE) -> Employee 19 | C22: =VLOOKUP(A22,'Employee Information'!A:C,3,FALSE) -> Finance | D22: =IFERROR(VLOOKUP(A22,'Performance Records'!A:B,2,FALSE),"PENDING REVIEW") -> PENDING REVIEW | E22: =IF(D22="PENDING REVIEW","PENDING REVIEW",IF(D22>90,"EXCELLENT",IF(D22>75,"GOOD",IF(D22>60,"AVERAGE","NEEDS IMPROVEMENT")))) -> PENDING REVIEW | F22: =IF(E22="PENDING REVIEW"," PENDING REVIEW",IF(OR(E22="EXCELLENT",E22="GOOD"),"ELIGIBLE","NOTELIGIBLE")) -> PENDING REVIEW
A23: =('Employee Information'!A21) -> EMP1020 | B23: =VLOOKUP(A23,'Employee Information'!A:D,2,FALSE) -> Employee 20 | C23: =VLOOKUP(A23,'Employee Information'!A:C,3,FALSE) -> Admin | D23: =IFERROR(VLOOKUP(A23,'Performance Records'!A:B,2,FALSE),"PENDING REVIEW") -> 65 | E23: =IF(D23="PENDING REVIEW","PENDING REVIEW",IF(D23>90,"EXCELLENT",IF(D23>75,"GOOD",IF(D23>60,"AVERAGE","NEEDS IMPROVEMENT")))) -> AVERAGE | F23: =IF(E23="PENDING REVIEW"," PENDING REVIEW",IF(OR(E23="EXCELLENT",E23="GOOD"),"ELIGIBLE","NOT ELIGIBLE")) -> NOT ELIGIBLE
A24: =('Employee Information'!A22) -> EMP1021 | B24: =VLOOKUP(A24,'Employee Information'!A:D,2,FALSE) -> Employee 21 | C24: =VLOOKUP(A24,'Employee Information'!A:C,3,FALSE) -> Sales | D24: =IFERROR(VLOOKUP(A24,'Performance Records'!A:B,2,FALSE),"PENDING REVIEW") -> 93 | E24: =IF(D24="PENDING REVIEW","PENDING REVIEW",IF(D24>90,"EXCELLENT",IF(D24>75,"GOOD",IF(D24>60,"AVERAGE","NEEDS IMPROVEMENT")))) -> EXCELLENT | F24: =IF(E24="PENDING REVIEW"," PENDING REVIEW",IF(OR(E24="EXCELLENT",E24="GOOD"),"ELIGIBLE","NOTELIGIBLE")) -> ELIGIBLE
A25: =('Employee Information'!A23) -> EMP1022 | B25: =VLOOKUP(A25,'Employee Information'!A:D,2,FALSE) -> Employee 22 | C25: =VLOOKUP(A25,'Employee Information'!A:C,3,FALSE) -> Operations | D25: =IFERROR(VLOOKUP(A25,'Performance Records'!A:B,2,FALSE),"PENDING REVIEW") -> 98 | E25: =IF(D25="PENDING REVIEW","PENDING REVIEW",IF(D25>90,"EXCELLENT",IF(D25>75,"GOOD",IF(D25>60,"AVERAGE","NEEDS IMPROVEMENT")))) -> EXCELLENT | F25: =IF(E25="PENDING REVIEW"," PENDING REVIEW",IF(OR(E25="EXCELLENT",E25="GOOD"),"ELIGIBLE","NOTELIGIBLE")) -> ELIGIBLE
A26: =('Employee Information'!A24) -> EMP1023 | B26: =VLOOKUP(A26,'Employee Information'!A:D,2,FALSE) -> Employee 23 | C26: =VLOOKUP(A26,'Employee Information'!A:C,3,FALSE) -> HR | D26: =IFERROR(VLOOKUP(A26,'Performance Records'!A:B,2,FALSE),"PENDING REVIEW") -> 88 | E26: =IF(D26="PENDING REVIEW","PENDING REVIEW",IF(D26>90,"EXCELLENT",IF(D26>75,"GOOD",IF(D26>60,"AVERAGE","NEEDS IMPROVEMENT")))) -> GOOD | F26: =IF(E26="PENDING REVIEW"," PENDING REVIEW",IF(OR(E26="EXCELLENT",E26="GOOD"),"ELIGIBLE","NOTELIGIBLE")) -> ELIGIBLE
A27: =('Employee Information'!A25) -> EMP1024 | B27: =VLOOKUP(A27,'Employee Information'!A:D,2,FALSE) -> Employee 24 | C27: =VLOOKUP(A27,'Employee Information'!A:C,3,FALSE) -> Sales | D27: =IFERROR(VLOOKUP(A27,'Performance Records'!A:B,2,FALSE),"PENDING REVIEW") -> 88 | E27: =IF(D27="PENDING REVIEW","PENDING REVIEW",IF(D27>90,"EXCELLENT",IF(D27>75,"GOOD",IF(D27>60,"AVERAGE","NEEDS IMPROVEMENT")))) -> GOOD | F27: =IF(E27="PENDING REVIEW"," PENDING REVIEW",IF(OR(E27="EXCELLENT",E27="GOOD"),"ELIGIBLE","NOTELIGIBLE")) -> ELIGIBLE
A28: =('Employee Information'!A26) -> EMP1025 | B28: =VLOOKUP(A28,'Employee Information'!A:D,2,FALSE) -> Employee 25 | C28: =VLOOKUP(A28,'Employee Information'!A:C,3,FALSE) -> IT | D28: =IFERROR(VLOOKUP(A28,'Performance Records'!A:B,2,FALSE),"PENDING REVIEW") -> 90 | E28: =IF(D28="PENDING REVIEW","PENDING REVIEW",IF(D28>90,"EXCELLENT",IF(D28>75,"GOOD",IF(D28>60,"AVERAGE","NEEDS IMPROVEMENT")))) -> GOOD | F28: =IF(E28="PENDING REVIEW"," PENDING REVIEW",IF(OR(E28="EXCELLENT",E28="GOOD"),"ELIGIBLE","NOTELIGIBLE")) -> ELIGIBLE
A29: =('Employee Information'!A27) -> EMP1026 | B29: =VLOOKUP(A29,'Employee Information'!A:D,2,FALSE) -> Employee 26 | C29: =VLOOKUP(A29,'Employee Information'!A:C,3,FALSE) -> Finance | D29: =IFERROR(VLOOKUP(A29,'Performance Records'!A:B,2,FALSE),"PENDING REVIEW") -> 68 | E29: =IF(D29="PENDING REVIEW","PENDING REVIEW",IF(D29>90,"EXCELLENT",IF(D29>75,"GOOD",IF(D29>60,"AVERAGE","NEEDS IMPROVEMENT")))) -> AVERAGE | F29: =IF(E29="PENDING REVIEW"," PENDING REVIEW",IF(OR(E29="EXCELLENT",E29="GOOD"),"ELIGIBLE","NOT ELIGIBLE")) -> NOT ELIGIBLE
A30: =('Employee Information'!A28) -> EMP1027 | B30: =VLOOKUP(A30,'Employee Information'!A:D,2,FALSE) -> Employee 27 | C30: =VLOOKUP(A30,'Employee Information'!A:C,3,FALSE) -> Admin | D30: =IFERROR(VLOOKUP(A30,'Performance Records'!A:B,2,FALSE),"PENDING REVIEW") -> 85 | E30: =IF(D30="PENDING REVIEW","PENDING REVIEW",IF(D30>90,"EXCELLENT",IF(D30>75,"GOOD",IF(D30>60,"AVERAGE","NEEDS IMPROVEMENT")))) -> GOOD | F30: =IF(E30="PENDING REVIEW"," PENDING REVIEW",IF(OR(E30="EXCELLENT",E30="GOOD"),"ELIGIBLE","NOTELIGIBLE")) -> ELIGIBLE
A31: =('Employee Information'!A29) -> EMP1028 | B31: =VLOOKUP(A31,'Employee Information'!A:D,2,FALSE) -> Employee 28 | C31: =VLOOKUP(A31,'Employee Information'!A:C,3,FALSE) -> Procurement | D31: =IFERROR(VLOOKUP(A31,'Performance Records'!A:B,2,FALSE),"PENDING REVIEW") -> 57 | E31: =IF(D31="PENDING REVIEW","PENDING REVIEW",IF(D31>90,"EXCELLENT",IF(D31>75,"GOOD",IF(D31>60,"AVERAGE","NEEDS IMPROVEMENT")))) -> NEEDS IMPROVEMENT | F31: =IF(E31="PENDING REVIEW"," PENDING REVIEW",IF(OR(E31="EXCELLENT",E31="GOOD"),"ELIGIBLE","NOT ELIGIBLE")) -> NOT ELIGIBLE
A32: =('Employee Information'!A30) -> EMP1029 | B32: =VLOOKUP(A32,'Employee Information'!A:D,2,FALSE) -> Employee 29 | C32: =VLOOKUP(A32,'Employee Information'!A:C,3,FALSE) -> Admin | D32: =IFERROR(VLOOKUP(A32,'Performance Records'!A:B,2,FALSE),"PENDING REVIEW") -> 56 | E32: =IF(D32="PENDING REVIEW","PENDING REVIEW",IF(D32>90,"EXCELLENT",IF(D32>75,"GOOD",IF(D32>60,"AVERAGE","NEEDS IMPROVEMENT")))) -> NEEDS IMPROVEMENT | F32: =IF(E32="PENDING REVIEW"," PENDING REVIEW",IF(OR(E32="EXCELLENT",E32="GOOD"),"ELIGIBLE","NOT ELIGIBLE")) -> NOT ELIGIBLE
A33: =('Employee Information'!A31) -> EMP1030 | B33: =VLOOKUP(A33,'Employee Information'!A:D,2,FALSE) -> Employee 30 | C33: =VLOOKUP(A33,'Employee Information'!A:C,3,FALSE) -> IT | D33: =IFERROR(VLOOKUP(A33,'Performance Records'!A:B,2,FALSE),"PENDING REVIEW") -> 52 | E33: =IF(D33="PENDING REVIEW","PENDING REVIEW",IF(D33>90,"EXCELLENT",IF(D33>75,"GOOD",IF(D33>60,"AVERAGE","NEEDS IMPROVEMENT")))) -> NEEDS IMPROVEMENT | F33: =IF(E33="PENDING REVIEW"," PENDING REVIEW",IF(OR(E33="EXCELLENT",E33="GOOD"),"ELIGIBLE","NOT ELIGIBLE")) -> NOT ELIGIBLE
A34: =('Employee Information'!A32) -> EMP1031 | B34: =VLOOKUP(A34,'Employee Information'!A:D,2,FALSE) -> Employee 31 | C34: =VLOOKUP(A34,'Employee Information'!A:C,3,FALSE) -> Sales | D34: =IFERROR(VLOOKUP(A34,'Performance Records'!A:B,2,FALSE),"PENDING REVIEW") -> 50 | E34: =IF(D34="PENDING REVIEW","PENDING REVIEW",IF(D34>90,"EXCELLENT",IF(D34>75,"GOOD",IF(D34>60,"AVERAGE","NEEDS IMPROVEMENT")))) -> NEEDS IMPROVEMENT | F34: =IF(E34="PENDING REVIEW"," PENDING REVIEW",IF(OR(E34="EXCELLENT",E34="GOOD"),"ELIGIBLE","NOT ELIGIBLE")) -> NOT ELIGIBLE
A35: =('Employee Information'!A33) -> EMP1032 | B35: =VLOOKUP(A35,'Employee Information'!A:D,2,FALSE) -> Employee 32 | C35: =VLOOKUP(A35,'Employee Information'!A:C,3,FALSE) -> Admin | D35: =IFERROR(VLOOKUP(A35,'Performance Records'!A:B,2,FALSE),"PENDING REVIEW") -> 92 | E35: =IF(D35="PENDING REVIEW","PENDING REVIEW",IF(D35>90,"EXCELLENT",IF(D35>75,"GOOD",IF(D35>60,"AVERAGE","NEEDS IMPROVEMENT")))) -> EXCELLENT | F35: =IF(E35="PENDING REVIEW"," PENDING REVIEW",IF(OR(E35="EXCELLENT",E35="GOOD"),"ELIGIBLE","NOTELIGIBLE")) -> ELIGIBLE
A36: =('Employee Information'!A34) -> EMP1033 | B36: =VLOOKUP(A36,'Employee Information'!A:D,2,FALSE) -> Employee 33 | C36: =VLOOKUP(A36,'Employee Information'!A:C,3,FALSE) -> Admin | D36: =IFERROR(VLOOKUP(A36,'Performance Records'!A:B,2,FALSE),"PENDING REVIEW") -> PENDING REVIEW | E36: =IF(D36="PENDING REVIEW","PENDING REVIEW",IF(D36>90,"EXCELLENT",IF(D36>75,"GOOD",IF(D36>60,"AVERAGE","NEEDS IMPROVEMENT")))) -> PENDING REVIEW | F36: =IF(E36="PENDING REVIEW"," PENDING REVIEW",IF(OR(E36="EXCELLENT",E36="GOOD"),"ELIGIBLE","NOTELIGIBLE")) -> PENDING REVIEW
A37: =('Employee Information'!A35) -> EMP1034 | B37: =VLOOKUP(A37,'Employee Information'!A:D,2,FALSE) -> Employee 34 | C37: =VLOOKUP(A37,'Employee Information'!A:C,3,FALSE) -> Operations | D37: =IFERROR(VLOOKUP(A37,'Performance Records'!A:B,2,FALSE),"PENDING REVIEW") -> 78 | E37: =IF(D37="PENDING REVIEW","PENDING REVIEW",IF(D37>90,"EXCELLENT",IF(D37>75,"GOOD",IF(D37>60,"AVERAGE","NEEDS IMPROVEMENT")))) -> GOOD | F37: =IF(E37="PENDING REVIEW"," PENDING REVIEW",IF(OR(E37="EXCELLENT",E37="GOOD"),"ELIGIBLE","NOTELIGIBLE")) -> ELIGIBLE
A38: =('Employee Information'!A36) -> EMP1035 | B38: =VLOOKUP(A38,'Employee Information'!A:D,2,FALSE) -> Employee 35 | C38: =VLOOKUP(A38,'Employee Information'!A:C,3,FALSE) -> Operations | D38: =IFERROR(VLOOKUP(A38,'Performance Records'!A:B,2,FALSE),"PENDING REVIEW") -> 55 | E38: =IF(D38="PENDING REVIEW","PENDING REVIEW",IF(D38>90,"EXCELLENT",IF(D38>75,"GOOD",IF(D38>60,"AVERAGE","NEEDS IMPROVEMENT")))) -> NEEDS IMPROVEMENT | F38: =IF(E38="PENDING REVIEW"," PENDING REVIEW",IF(OR(E38="EXCELLENT",E38="GOOD"),"ELIGIBLE","NOT ELIGIBLE")) -> NOT ELIGIBLE
A39: =('Employee Information'!A37) -> EMP1036 | B39: =VLOOKUP(A39,'Employee Information'!A:D,2,FALSE) -> Employee 36 | C39: =VLOOKUP(A39,'Employee Information'!A:C,3,FALSE) -> Admin | D39: =IFERROR(VLOOKUP(A39,'Performance Records'!A:B,2,FALSE),"PENDING REVIEW") -> PENDING REVIEW | E39: =IF(D39="PENDING REVIEW","PENDING REVIEW",IF(D39>90,"EXCELLENT",IF(D39>75,"GOOD",IF(D39>60,"AVERAGE","NEEDS IMPROVEMENT")))) -> PENDING REVIEW | F39: =IF(E39="PENDING REVIEW"," PENDING REVIEW",IF(OR(E39="EXCELLENT",E39="GOOD"),"ELIGIBLE","NOTELIGIBLE")) -> PENDING REVIEW
A40: =('Employee Information'!A38) -> EMP1037 | B40: =VLOOKUP(A40,'Employee Information'!A:D,2,FALSE) -> Employee 37 | C40: =VLOOKUP(A40,'Employee Information'!A:C,3,FALSE) -> IT | D40: =IFERROR(VLOOKUP(A40,'Performance Records'!A:B,2,FALSE),"PENDING REVIEW") -> 65 | E40: =IF(D40="PENDING REVIEW","PENDING REVIEW",IF(D40>90,"EXCELLENT",IF(D40>75,"GOOD",IF(D40>60,"AVERAGE","NEEDS IMPROVEMENT")))) -> AVERAGE | F40: =IF(E40="PENDING REVIEW"," PENDING REVIEW",IF(OR(E40="EXCELLENT",E40="GOOD"),"ELIGIBLE","NOT ELIGIBLE")) -> NOT ELIGIBLE
A41: =('Employee Information'!A39) -> EMP1038 | B41: =VLOOKUP(A41,'Employee Information'!A:D,2,FALSE) -> Employee 38 | C41: =VLOOKUP(A41,'Employee Information'!A:C,3,FALSE) -> Admin | D41: =IFERROR(VLOOKUP(A41,'Performance Records'!A:B,2,FALSE),"PENDING REVIEW") -> 98 | E41: =IF(D41="PENDING REVIEW","PENDING REVIEW",IF(D41>90,"EXCELLENT",IF(D41>75,"GOOD",IF(D41>60,"AVERAGE","NEEDS IMPROVEMENT")))) -> EXCELLENT | F41: =IF(E41="PENDING REVIEW"," PENDING REVIEW",IF(OR(E41="EXCELLENT",E41="GOOD"),"ELIGIBLE","NOTELIGIBLE")) -> ELIGIBLE
...
